Workbook

Sheet pokemon
A1: # | B1: Name | C1: Type 1 | D1: Type 2 | E1: Total | F1: HP | G1: Attack | H1: Defense | I1: Sp. Atk | J1: Sp. Def | K1: Speed | L1: Generation | M1: Legendary
A2: 1 | B2: Bulbasaur | C2: Grass | D2: Poison | E2: 318 | F2: 45 | G2: 49 | H2: 49 | I2: 65 | J2: 65 | K2: 45 | L2: 1 | M2: FALSE
A3: 2 | B3: Ivysaur | C3: Grass | D3: Poison | E3: 405 | F3: 60 | G3: 62 | H3: 63 | I3: 80 | J3: 80 | K3: 60 | L3: 1 | M3: FALSE
A4: 3 | B4: Venusaur | C4: Grass | D4: Poison | E4: 525 | F4: 80 | G4: 82 | H4: 83 | I4: 100 | J4: 100 | K4: 80 | L4: 1 | M4: FALSE
A5: 4 | B5: Charmander | C5: Fire | E5: 309 | F5: 39 | G5: 52 | H5: 43 | I5: 60 | J5: 50 | K5: 65 | L5: 1 | M5: FALSE
A6: 5 | B6: Charmeleon | C6: Fire | E6: 405 | F6: 58 | G6: 64 | H6: 58 | I6: 80 | J6: 65 | K6: 80 | L6: 1 | M6: FALSE
A7: 6 | B7: Charizard | C7: Fire | D7: Flying | E7: 534 | F7: 78 | G7: 84 | H7: 78 | I7: 109 | J7: 85 | K7: 100 | L7: 1 | M7: FALSE
A8: 7 | B8: Squirtle | C8: Water | E8: 314 | F8: 44 | G8: 48 | H8: 65 | I8: 50 | J8: 64 | K8: 43 | L8: 1 | M8: FALSE
A9: 8 | B9: Wartortle | C9: Water | E9: 405 | F9: 59 | G9: 63 | H9: 80 | I9: 65 | J9: 80 | K9: 58 | L9: 1 | M9: FALSE
A10: 9 | B10: Blastoise | C10: Water | E10: 530 | F10: 79 | G10: 83 | H10: 100 | I10: 85 | J10: 105 | K10: 78 | L10: 1 | M10: FALSE
A11: 10 | B11: Caterpie | C11: Bug | E11: 195 | F11: 45 | G11: 30 | H11: 35 | I11: 20 | J11: 20 | K11: 45 | L11: 1 | M11: FALSE
A12: 11 | B12: Metapod | C12: Bug | E12: 205 | F12: 50 | G12: 20 | H12: 55 | I12: 25 | J12: 25 | K12: 30 | L12: 1 | M12: FALSE
A13: 12 | B13: Butterfree | C13: Bug | D13: Flying | E13: 395 | F13: 60 | G13: 45 | H13: 50 | I13: 90 | J13: 80 | K13: 70 | L13: 1 | M13: FALSE
A14: 13 | B14: Weedle | C14: Bug | D14: Poison | E14: 195 | F14: 40 | G14: 35 | H14: 30 | I14: 20 | J14: 20 | K14: 50 | L14: 1 | M14: FALSE
A15: 14 | B15: Kakuna | C15: Bug | D15: Poison | E15: 205 | F15: 45 | G15: 25 | H15: 50 | I15: 25 | J15: 25 | K15: 35 | L15: 1 | M15: FALSE
A16: 15 | B16: Beedrill | C16: Bug | D16: Poison | E16: 395 | F16: 65 | G16: 90 | H16: 40 | I16: 45 | J16: 80 | K16: 75 | L16: 1 | M16: FALSE
A17: 16 | B17: Pidgey | C17: Normal | D17: Flying | E17: 251 | F17: 40 | G17: 45 | H17: 40 | I17: 35 | J17: 35 | K17: 56 | L17: 1 | M17: FALSE
A18: 17 | B18: Pidgeotto | C18: Normal | D18: Flying | E18: 349 | F18: 63 | G18: 60 | H18: 55 | I18: 50 | J18: 50 | K18: 71 | L18: 1 | M18: FALSE
A19: 18 | B19: Pidgeot | C19: Normal | D19: Flying | E19: 479 | F19: 83 | G19: 80 | H19: 75 | I19: 70 | J19: 70 | K19: 101 | L19: 1 | M19: FALSE
A20: 19 | B20: Rattata | C20: Normal | E20: 253 | F20: 30 | G20: 56 | H20: 35 | I20: 25 | J20: 35 | K20: 72 | L20: 1 | M20: FALSE
A21: 20 | B21: Raticate | C21: Normal | E21: 413 | F21: 55 | G21: 81 | H21: 60 | I21: 50 | J21: 70 | K21: 97 | L21: 1 | M21: FALSE
A22: 21 | B22: Spearow | C22: Normal | D22: Flying | E22: 262 | F22: 40 | G22: 60 | H22: 30 | I22: 31 | J22: 31 | K22: 70 | L22: 1 | M22: FALSE
A23: 22 | B23: Fearow | C23: Normal | D23: Flying | E23: 442 | F23: 65 | G23: 90 | H23: 65 | I23: 61 | J23: 61 | K23: 100 | L23: 1 | M23: FALSE
A24: 23 | B24: Ekans | C24: Poison | E24: 288 | F24: 35 | G24: 60 | H24: 44 | I24: 40 | J24: 54 | K24: 55 | L24: 1 | M24: FALSE
A25: 24 | B25: Arbok | C25: Poison | E25: 438 | F25: 60 | G25: 85 | H25: 69 | I25: 65 | J25: 79 | K25: 80 | L25: 1 | M25: FALSE
A26: 25 | B26: Pikachu | C26: Electric | E26: 320 | F26: 35 | G26: 55 | H26: 40 | I26: 50 | J26: 50 | K26: 90 | L26: 1 | M26: FALSE
A27: 26 | B27: Raichu | C27: Electric | E27: 485 | F27: 60 | G27: 90 | H27: 55 | I27: 90 | J27: 80 | K27: 110 | L27: 1 | M27: FALSE
A28: 27 | B28: Sandshrew | C28: Ground | E28: 300 | F28: 50 | G28: 75 | H28: 85 | I28: 20 | J28: 30 | K28: 40 | L28: 1 | M28: FALSE
A29: 28 | B29: Sandslash | C29: Ground | E29: 450 | F29: 75 | G29: 100 | H29: 110 | I29: 45 | J29: 55 | K29: 65 | L29: 1 | M29: FALSE
A30: 29 | B30: Nidoran H | C30: Poison | E30: 275 | F30: 55 | G30: 47 | H30: 52 | I30: 40 | J30: 40 | K30: 41 | L30: 1 | M30: FALSE
A31: 30 | B31: Nidorina | C31: Poison | E31: 365 | F31: 70 | G31: 62 | H31: 67 | I31: 55 | J31: 55 | K31: 56 | L31: 1 | M31: FALSE
A32: 31 | B32: Nidoqueen | C32: Poison | D32: Ground | E32: 505 | F32: 90 | G32: 92 | H32: 87 | I32: 75 | J32: 85 | K32: 76 | L32: 1 | M32: FALSE
A33: 32 | B33: Nidoran M | C33: Poison | E33: 273 | F33: 46 | G33: 57 | H33: 40 | I33: 40 | J33: 40 | K33: 50 | L33: 1 | M33: FALSE
A34: 33 | B34: Nidorino | C34: Poison | E34: 365 | F34: 61 | G34: 72 | H34: 57 | I34: 55 | J34: 55 | K34: 65 | L34: 1 | M34: FALSE
A35: 34 | B35: Nidoking | C35: Poison | D35: Ground | E35: 505 | F35: 81 | G35: 102 | H35: 77 | I35: 85 | J35: 75 | K35: 85 | L35: 1 | M35: FALSE
A36: 35 | B36: Clefairy | C36: Fairy | E36: 323 | F36: 70 | G36: 45 | H36: 48 | I36: 60 | J36: 65 | K36: 35 | L36: 1 | M36: FALSE
A37: 36 | B37: Clefable | C37: Fairy | E37: 483 | F37: 95 | G37: 70 | H37: 73 | I37: 95 | J37: 90 | K37: 60 | L37: 1 | M37: FALSE
A38: 37 | B38: Vulpix | C38: Fire | E38: 299 | F38: 38 | G38: 41 | H38: 40 | I38: 50 | J38: 65 | K38: 65 | L38: 1 | M38: FALSE
A39: 38 | B39: Ninetales | C39: Fire | E39: 505 | F39: 73 | G39: 76 | H39: 75 | I39: 81 | J39: 100 | K39: 100 | L39: 1 | M39: FALSE
A40: 39 | B40: Jigglypuff | C40: Normal | D40: Fairy | E40: 270 | F40: 115 | G40: 45 | H40: 20 | I40: 45 | J40: 25 | K40: 20 | L40: 1 | M40: FALSE
...

Sheet PKMN BULBAP
A1: # | B1: Cod | C1: Pokémon | D1: HP | E1: Attack | F1: Defense | G1: Sp. Attack | H1: Sp. Defense | I1: Speed | J1: Total | K1: Average
A2: 1 | B2: 001O | C2: Bulbasaur | D2: 45 | E2: 49 | F2: 49 | G2: 65 | H2: 65 | I2: 45 | J2: 318 | K2: 53 | L2: =LEN(B2) -> 4
A3: 2 | B3: 002O | C3: Ivysaur | D3: 60 | E3: 62 | F3: 63 | G3: 80 | H3: 80 | I3: 60 | J3: 405 | K3: 67.5 | L3: =LEN(B3) -> 4
A4: 3 | B4: 003O | C4: Venusaur | D4: 80 | E4: 82 | F4: 83 | G4: 100 | H4: 100 | I4: 80 | J4: 525 | K4: 87.5 | L4: =LEN(B4) -> 4
A5: 3 | B5: 003M | C5: Venusaur (Mega Venusaur) | D5: 80 | E5: 100 | F5: 123 | G5: 122 | H5: 120 | I5: 80 | J5: 625 | K5: 104.17 | L5: =LEN(B5) -> 4
A6: 4 | B6: 004O | C6: Charmander | D6: 39 | E6: 52 | F6: 43 | G6: 60 | H6: 50 | I6: 65 | J6: 309 | K6: 51.5 | L6: =LEN(B6) -> 4
A7: 5 | B7: 005O | C7: Charmeleon | D7: 58 | E7: 64 | F7: 58 | G7: 80 | H7: 65 | I7: 80 | J7: 405 | K7: 67.5 | L7: =LEN(B7) -> 4
A8: 6 | B8: 006O | C8: Charizard | D8: 78 | E8: 84 | F8: 78 | G8: 109 | H8: 85 | I8: 100 | J8: 534 | K8: 89 | L8: =LEN(B8) -> 4
A9: 6 | B9: 006X | C9: Charizard (Mega Charizard X) | D9: 78 | E9: 130 | F9: 111 | G9: 130 | H9: 85 | I9: 100 | J9: 634 | K9: 105.67 | L9: =LEN(B9) -> 4
A10: 6 | B10: 006Y | C10: Charizard (Mega Charizard Y) | D10: 78 | E10: 104 | F10: 78 | G10: 159 | H10: 115 | I10: 100 | J10: 634 | K10: 105.67 | L10: =LEN(B10) -> 4
A11: 7 | B11: 007O | C11: Squirtle | D11: 44 | E11: 48 | F11: 65 | G11: 50 | H11: 64 | I11: 43 | J11: 314 | K11: 52.33 | L11: =LEN(B11) -> 4
A12: 8 | B12: 008O | C12: Wartortle | D12: 59 | E12: 63 | F12: 80 | G12: 65 | H12: 80 | I12: 58 | J12: 405 | K12: 67.5 | L12: =LEN(B12) -> 4
A13: 9 | B13: 009O | C13: Blastoise | D13: 79 | E13: 83 | F13: 100 | G13: 85 | H13: 105 | I13: 78 | J13: 530 | K13: 88.33 | L13: =LEN(B13) -> 4
... A1063: 905 | B1063: 905T | C1063: Enamorus (Therian Forme) | D1063: 74 | E1063: 115 | F1063: 110 | G1063: 135 | H1063: 100 | I1063: 46 | J1063: 580 | K1063: 96.67 | L1063: =LEN(B1063) -> 4
D1065: 1-9HP = 1HP 10-39HP = 2HP 40-59HP = 3HP 60-79HP = 4HP 80-99HP = 5HP 100-119HP = 6HP 120-139HP = 7HP 140-160HP = 8HP 161-190HP = 9HP >190HP = 10 HP | E1065: 5-44At = 1d4 45-84At = 1d6 85-124 = 1d8 125-144 = 1d10 >145 = 1d12 | F1065: de 0 a 29 = 0 de 30 a 59 = 1 de 60 a 79 = 2 de 80 a 99 = 3 de 100 a 119 = 4 de 120 a 139 = 5 de 140 a 169 = 6 de 170 a 199 = 7 +200 = 8 | G1065: 5-44At = 1d4 45-84At = 1d6 85-124 = 1d8 125-144 = 1d10 >145 = 1d12 | H1065: de 0 a 29 = 0 de 30 a 59 = 1 de 60 a 79 = 2 de 80 a 99 = 3 de 100 a 119 = 4 de 120 a 139 = 5 de 140 a 169 = 6 de 170 a 199 = 7 +200 = 8 | I1065: 1-9HP = 1HP 10-39HP = 2HP 40-59HP = 3HP 60-79HP = 4HP 80-99HP = 5HP 100-119HP = 6HP 120-139HP = 7HP 140-159HP = 8HP 160-180HP = 9HP >180HP = 10 HP

Sheet Evolution Special
B2: Regions | C2: Gender | D2: Time | E2: Move | F2: Weather | G2: Benefits | H2: Hability | I2: Stat | J2: Friend
B3: Kanto+ | C3: Male | D3: Day | E3: M1 | F3: Clear | G3: Normal, Grass | H3: H1 | I3: ATQ < SPD | J3: 30
B4: Johto+ | C4: Female | D4: Night | E4: M2 | F4: Cloudy | G4: Fighting, Poison, Dark | H4: H2 | I4: ATQ > SPD | J4: 45
B5: Hoenn+ | E5: M3 | F5: Rain | G5: Water, Bug | I5: ATQ = SPD | J5: 60
B6: Shinnoh+ | E6: M4 | F6: Thunderstorm | G6: Water, Electric, Dragon | J6: 75
B7: Unova+ | F7: Snow | G7: Ice
B8: Kalos+ | F8: Blizzard | G8: Ice, Steel
B9: Alola+ | F9: Harsh sunlight | G9: Fire, Ground
B10: Galar+ | F10: Sandstorm | G10: Ground, Rock
B11: Hisui+ | F11: Fog | G11: Psychic, Ghost, Fairy
F12: Windy | G12: Flying

Sheet Breed
F1: Male | G1: Female | M1: Egg 1
C2: 1 | D2: Bulbasaur | E2: Bulbasaur | F2: 0.85 | G2: 0.15 | J2: 23 | K2: Ekans | L2: Ekans | M2: Field
C3: 2 | D3: Ivysaur | E3: Ivysaur | F3: 0.85 | G3: 0.15 | J3: 24 | K3: Arbok | L3: Arbok | M3: Field
C4: 3 | D4: Venusaur | E4: Venusaur | F4: 0.85 | G4: 0.15 | J4: 25 | K4: Pikachu | L4: Pikachu | M4: Fairy
C5: 4 | D5: Charmander | E5: Charmander | F5: 0.85 | G5: 0.15 | J5: 26 | K5: Raichu | L5: Raichu | M5: Fairy
C6: 5 | D6: Charmeleon | E6: Charmeleon | F6: 0.85 | G6: 0.15 | J6: 27 | K6: Sandshrew | L6: Sandshrew | M6: Field
C7: 6 | D7: Charizard | E7: Charizard | F7: 0.85 | G7: 0.15 | J7: 28 | K7: Sandslash | L7: Sandslash | M7: Field
C8: 7 | D8: Squirtle | E8: Squirtle | F8: 0.85 | G8: 0.15 | J8: 29 | K8: Nidoran♀ | L8: Nidoran♀ | M8: Field
C9: 8 | D9: Wartortle | E9: Wartortle | F9: 0.85 | G9: 0.15 | J9: 30 | K9: Nidorina | L9: Nidorina | M9: Undiscovered
C10: 9 | D10: Blastoise | E10: Blastoise | F10: 0.85 | G10: 0.15 | J10: 31 | K10: Nidoqueen | L10: Nidoqueen | M10: Undiscovered
C11: 10 | D11: Caterpie | E11: Caterpie | F11: 0.5 | G11: 0.5 | J11: 164 | K11: Noctowl | L11: Noctowl | M11: Flying
C12: 11 | D12: Metapod | E12: Metapod | F12: 0.5 | G12: 0.5 | J12: 165 | K12: Ledyba | L12: Ledyba | M12: Bug
C13: 12 | D13: Butterfree | E13: Butterfree | F13: 0.5 | G13: 0.5 | J13: 166 | K13: Ledian | L13: Ledian | M13: Bug
... C81: 80 | D81: Slowbro | E81: Slowbro | F81: 0.5 | G81: 0.5 | J81: 214 | K81: Heracross | L81: Heracross | M81: Bug
C82: 81 | D82: Magnemite | E82: Magnemite | F82: - | G82: - | J82: 777 | K82: Togedemaru | L82: Togedemaru | M82: Fairy
C83: 82 | D83: Magneton | E83: Magneton | F83: - | G83: - | J83: 778 | K83: Mimikyu | L83: Mimikyu | M83: Amorphous
C84: 83 | D84: Farfetch'd | E84: Farfetch'd | F84: 0.5 | G84: 0.5 | J84: 215 | K84: Sneasel | L84: Sneasel | M84: Field
C85: 84 | D85: Doduo | E85: Doduo | F85: 0.5 | G85: 0.5 | J85: 216 | K85: Teddiursa | L85: Teddiursa | M85: Field
C86: 85 | D86: Dodrio | E86: Dodrio | F86: 0.5 | G86: 0.5 | J86: 217 | K86: Ursaring | L86: Ursaring | M86: Field
C87: 86 | D87: Seel | E87: Seel | F87: 0.5 | G87: 0.5 | J87: 218 | K87: Slugma | L87: Slugma | M87: Amorphous
C88: 87 | D88: Dewgong | E88: Dewgong | F88: 0.5 | G88: 0.5 | J88: 219 | K88: Magcargo | L88: Magcargo | M88: Amorphous
C89: 88 | D89: Grimer | E89: Grimer | F89: 0.5 | G89: 0.5 | J89: 220 | K89: Swinub | L89: Swinub | M89: Field
C90: 89 | D90: Muk | E90: Muk | F90: 0.5 | G90: 0.5 | J90: 221 | K90: Piloswine | L90: Piloswine | M90: Field
C91: 90 | D91: Shellder | E91: Shellder | F91: 0.5 | G91: 0.5 | J91: 222 | K91: Corsola | L91: Corsola | M91: Water 3
C92: 91 | D92: Cloyster | E92: Cloyster | F92: 0.5 | G92: 0.5 | J92: 223 | K92: Remoraid | L92: Remoraid | M92: Water 2
C93: 92 | D93: Gastly | E93: Gastly | F93: 0.5 | G93: 0.5 | J93: 224 | K93: Octillery | L93: Octillery | M93: Water 2
C94: 93 | D94: Haunter | E94: Haunter | F94: 0.5 | G94: 0.5 | J94: 225 | K94: Delibird | L94: Delibird | M94: Field
C95: 94 | D95: Gengar | E95: Gengar | F95: 0.5 | G95: 0.5 | J95: 226 | K95: Mantine | L95: Mantine | M95: Water 3
... C100: 99 | D100: Kingler | E100: Kingler | F100: 0.5 | G100: 0.5 | J100: 231 | K100: Phanpy | L100: Phanpy | M100: Field
C101: 100 | D101: Voltorb | E101: Voltorb | F101: - | G101: - | J101: 779 | K101: Bruxish | L101: Bruxish | M101: Water 2
C102: 101 | D102: Electrode | E102: Electrode | F102: - | G102: - | J102: 780 | K102: Drampa | L102: Drampa | M102: Dragon
C103: 102 | D103: Exeggcute | E103: Exeggcute | F103: 0.5 | G103: 0.5 | J103: 232 | K103: Donphan | L103: Donphan | M103: Field
C104: 103 | D104: Exeggutor | E104: Exeggutor | F104: 0.5 | G104: 0.5 | J104: 233 | K104: Porygon2 | L104: Porygon2 | M104: Mineral
C105: 104 | D105: Cubone | E105: Cubone | F105: 0.5 | G105: 0.5 | J105: 234 | K105: Stantler | L105: Stantler | M105: Field
C106: 105 | D106: Marowak | E106: Marowak | F106: 0.5 | G106: 0.5 | J106: 235 | K106: Smeargle | L106: Smeargle | M106: Field
C107: 106 | D107: Hitmonlee | E107: Hitmonlee | F107: 1 | G107: 0 | J107: 4 | K107: Charmander | L107: Charmander | M107: Dragon
C108: 107 | D108: Hitmonchan | E108: Hitmonchan | F108: 1 | G108: 0 | J108: 5 | K108: Charmeleon | L108: Charmeleon | M108: Dragon
C109: 108 | D109: Lickitung | E109: Lickitung | F109: 0.5 | G109: 0.5 | J109: 236 | K109: Tyrogue | L109: Tyrogue | M109: Undiscovered
C110: 109 | D110: Koffing | E110: Koffing | F110: 0.5 | G110: 0.5 | J110: 237 | K110: Hitmontop | L110: Hitmontop | M110: Human-Like
C111: 110 | D111: Weezing | E111: Weezing | F111: 0.5 | G111: 0.5 | J111: 238 | K111: Smoochum | L111: Smoochum | M111: Undiscovered
...

Sheet Pokemon Db
A1: Real Games | Z1: Pokemon Tabletop Stats | AE1: Habilities and Moves | AM1: Resistances and Weaknessess
A2: Basic | G2: Evolution | L2: Special contditions to get this stage | S2: Original stats | AE2: Habilities | AI2: Moves
A3: # | B3: Name | C3: Generation | D3: Type 1 | E3: Type 2 | F3: TAG | G3: Stage | H3: Family | I3: Chain nº | J3: Preevolution | K3: Evolves with | L3: Friend | M3: Gender | N3: Move | O3: Weather | P3: Time | Q3: Hability | R3: Stat | S3: Total | T3: HP | U3: Attack | V3: Defense | W3: Sp. Atk | X3: Sp. Def | Y3: Speed | Z3: HP | AA3: Attack | AB3: Speed | AC3: Overall | AD3: Tier | AE3: Habilidad 1 | AF3: Tipo | AG3: Habilidad 2 | AH3: Tipo | AI3: Movimiento 1 | AJ3: Movimiento 2 | AK3: Movimiento 3 | AL3: Movimiento 4 | AM3: Debilidades | AN3: Resistencias | AO3: Debilidades simp. | AP3: Resistencias Simp.
A4: 149 | B4: Dragonite | C4: Kanto | D4: Dragon | E4: Flying | F4: NORMAL | G4: L | H4: Dratini | I4: 31 | J4: Dragonair | K4: Fully evolved | S4: 600 | T4: 91 | U4: 134 | V4: 95 | W4: 100 | X4: 100 | Y4: 80 | Z4: 19 | AA4: 9.5 | AB4: 8 | AC4: =SUM(Z4:AB4) -> 36.5 | AD4: A | AE4: Ilusión | AF4: C | AH4: C | AI4: Vel. Extrema | AJ4: Cometa draco | AK4: Trueno | AL4: Danza dragón | AM4: Hada / Dragón / Roca / Hielo | AN4: Tierra / Planta / Lucha / Fuego / Bicho / Agua | AO4: Hada / Dragón / Roca / Hielo | AP4: Tierra / Planta / Lucha / Fuego / Bicho / Agua
A5: 248 | B5: Tyranitar | C5: Johto | D5: Rock | E5: Dark | F5: NORMAL | G5: L | H5: Larvitar | I5: 31 | J5: Pupitar | K5: Fully evolved | S5: 600 | T5: 100 | U5: 134 | V5: 110 | W5: 95 | X5: 100 | Y5: 61 | Z5: 21 | AA5: 10.5 | AB5: 6 | AC5: =SUM(Z5:AB5) -> 37.5 | AD5: S
A6: 136 | B6: Flareon | C6: Kanto | D6: Fire | F6: NORMAL | G6: L | H6: Eevee | I6: 23 | J6: Eevee | K6: Fully evolved | O6: Harsh sunlight | S6: 525 | T6: 65 | U6: 130 | V6: 60 | W6: 95 | X6: 110 | Y6: 65 | Z6: 16 | AA6: 8.5 | AB6: 7 | AC6: =SUM(Z6:AB6) -> 31.5 | AD6: B | AE6: Agallas | AF6: C | AH6: C | AI6: Bola sombra | AJ6: Humareda | AK6: Arenas ardientes | AL6: Fuerza bruta | AM6: Tierra / Roca / Agua | AN6: Bicho / Fuego / Acero / Hielo / Planta / Hada | AO6: Tierra / Roca / Agua | AP6: Bicho / Fuego / Acero / Hielo / Planta / Hada
A7: 250 | B7: Ho-oh | C7: Johto | D7: Fire | E7: Flying | F7: LEGEND | G7: L | H7: Ho-oh | I7: 11 | J7: - | K7: Fully evolved | S7: 680 | T7: 106 | U7: 130 | V7: 90 | W7: 110 | X7: 154 | Y7: 90 | Z7: 23 | AA7: 12 | AB7: 9 | AC7: =SUM(Z7:AB7) -> 44 | AD7: S
A8: 99 | B8: Kingler | C8: Kanto | D8: Water | F8: NORMAL | G8: L | H8: Krabby | I8: 21 | J8: Krabby | K8: Fully evolved | S8: 475 | T8: 55 | U8: 130 | V8: 115 | W8: 50 | X8: 50 | Y8: 75 | Z8: 15 | AA8: 8.5 | AB8: 8 | AC8: =SUM(Z8:AB8) -> 31.5 | AD8: B | AE8: Defensor | AF8: T | AH8: T | AI8: Tijera X | AJ8: Martillazo | AK8: Fuerza bruta | AL8: Fuerza equina | AM8: Eléctrico / Planta | AN8: Agua / Acero / Fuego / Hielo | AO8: Eléctrico / Planta | AP8: Agua / Acero / Fuego / Hielo
A9: 68 | B9: Machamp | C9: Kanto | D9: Fighting | F9: NORMAL | G9: L | H9: Machop | I9: 31 | J9: Machoke | K9: Fully evolved | S9: 505 | T9: 90 | U9: 130 | V9: 80 | W9: 65 | X9: 85 | Y9: 55 | Z9: 17 | AA9: 7.5 | AB9: 6 | AC9: =SUM(Z9:AB9) -> 30.5 | AD9: B | AE9: Peleón | AF9: T | AH9: T | AI9: Puño bala | AJ9: Tajo cruzado | AK9: Puño hielo | AL9: Lariat oscuro | AM9: Volador / Hada / Psíquico | AN9: Bicho / Siniestro / Roca | AO9: Volador / Hada / Psíquico | AP9: Bicho / Siniestro / Roca
A10: 112 | B10: Rhydon | C10: Kanto | D10: Ground | E10: Rock | F10: NORMAL | G10: L | H10: Rhyhorn | I10: 21 | J10: Rhyhorn | K10: Fully evolved | S10: 485 | T10: 105 | U10: 130 | V10: 120 | W10: 45 | X10: 45 | Y10: 40 | Z10: 18 | AA10: 7.5 | AB10: 4 | AC10: =SUM(Z10:AB10) -> 29.5 | AD10: B | AE10: Irascible | AF10: C | AH10: C | AI10: Megacuerno | AJ10: Cuerpo pesado | AK10: Carga dragón | AL10: Terremoto | AM10: Acero / Lucha / Tierra / Hielo / Planta / Agua | AN10: Eléctrico / Veneno / Fuego / Volador / Normal / Roca | AO10: Acero / Lucha / Tierra / Hielo / Planta / Agua | AP10: Eléctrico / Veneno / Fuego / Volador / Normal / Roca
A11: 212 | B11: Scizor | C11: Johto | D11: Bug | E11: Steel | F11: NORMAL | G11: L | H11: Scyther | I11: 21 | J11: Scyther | K11: Fully evolved | N11: M4 | S11: 500 | T11: 70 | U11: 130 | V11: 100 | W11: 55 | X11: 80 | Y11: 65 | Z11: 17 | AA11: 8.5 | AB11: 7 | AC11: =SUM(Z11:AB11) -> 32.5 | AD11: B
A12: 217 | B12: Ursaring | C12: Johto | D12: Normal | F12: NORMAL | G12: L | H12: Teddiursa | I12: 21 | J12: Teddiursa | K12: Fully evolved | S12: 500 | T12: 90 | U12: 130 | V12: 75 | W12: 75 | X12: 75 | Y12: 55 | Z12: 16 | AA12: 9.5 | AB12: 6 | AC12: =SUM(Z12:AB12) -> 31.5 | AD12: B
A13: 214 | B13: Heracross | C13: Johto | D13: Bug | E13: Fighting | F13: NORMAL | G13: L | H13: Heracross | I13: 11 | J13: - | K13: Fully evolved | S13: 500 | T13: 80 | U13: 125 | V13: 75 | W13: 40 | X13: 95 | Y13: 85 | Z13: 17 | AA13: 7.5 | AB13: 9 | AC13: =SUM(Z13:AB13) -> 33.5 | AD13: A
A14: 130 | B14: Gyarados | C14: Kanto | D14: Water | E14: Flying | F14: NORMAL | G14: L | H14: Magikarp | I14: 21 | J14: Magikarp | K14: Fully evolved | S14: 540 | T14: 95 | U14: 125 | V14: 79 | W14: 60 | X14: 100 | Y14: 81 | Z14: 18 | AA14: 9.5 | AB14: 8 | AC14: =SUM(Z14:AB14) -> 35.5 | AD14: A | AE14: Autoestima | AF14: C | AH14: C | AI14: Cascada | AJ14: Triturar | AK14: Enfado | AL14: Danza dragón | AM14: Eléctrico / Roca | AN14: Tierra / Bicho / Fuego / Acero / Agua / Lucha | AO14: Eléctrico / Roca | AP14: Tierra / Bicho / Fuego / Acero / Agua / Lucha
A15: 127 | B15: Pinsir | C15: Kanto | D15: Bug | F15: NORMAL | G15: L | H15: Pinsir | I15: 11 | J15: - | K15: Fully evolved | S15: 500 | T15: 65 | U15: 125 | V15: 100 | W15: 55 | X15: 70 | Y15: 85 | Z15: 16 | AA15: 7 | AB15: 9 | AC15: =SUM(Z15:AB15) -> 32 | AD15: B | AE15: Duelista | AF15: T | AH15: T | AI15: Picadura | AJ15: A Bocajarro | AK15: Avalancha | AL15: Guillotina | AM15: Volador / Fuego / Roca | AN15: Planta / Tierra / Lucha | AO15: Volador / Fuego / Roca | AP15: Planta / Tierra / Lucha
A16: 76 | B16: Golem | C16: Kanto | D16: Rock | E16: Ground | F16: NORMAL | G16: L | H16: Geodude | I16: 31 | J16: Graveler | K16: Fully evolved | S16: 495 | T16: 80 | U16: 120 | V16: 130 | W16: 55 | X16: 65 | Y16: 45 | Z16: 18 | AA16: 7.5 | AB16: 5 | AC16: =SUM(Z16:AB16) -> 30.5 | AD16: B | AE16: Autodestrucción | AF16: T | AG16: Robustez | AH16: C | AI16: Avalancha | AJ16: Terremoto | AK16: Puño fuego | AL16: Aligerar | AM16: Acero / Lucha / Tierra / Hielo / Planta / Agua | AN16: Eléctrico / Veneno / Fuego / Volador / Normal / Roca | AO16: Acero / Lucha / Tierra / Hielo / Planta / Agua | AP16: Eléctrico / Veneno / Fuego / Volador / Normal / Roca
A17: 232 | B17: Donphan | C17: Johto | D17: Ground | F17: NORMAL | G17: L | H17: Phanpy | I17: 21 | J17: Phanpy | K17: Fully evolved | S17: 500 | T17: 90 | U17: 120 | V17: 120 | W17: 60 | X17: 60 | Y17: 50 | Z17: 18 | AA17: 8.5 | AB17: 5 | AC17: =SUM(Z17:AB17) -> 31.5 | AD17: B
A18: 210 | B18: Granbull | C18: Johto | D18: Fairy | F18: NORMAL | G18: L | H18: Snubbull | I18: 21 | J18: Snubbull | K18: Fully evolved | S18: 450 | T18: 90 | U18: 120 | V18: 75 | W18: 60 | X18: 60 | Y18: 45 | Z18: 15 | AA18: 8.5 | AB18: 5 | AC18: =SUM(Z18:AB18) -> 28.5 | AD18: C
A19: 106 | B19: Hitmonlee | C19: Kanto | D19: Fighting | F19: NORMAL | G19: L | H19: Tyrogue | I19: 21 | J19: Tyrogue | K19: Fully evolved | R19: ATQ < SPD | S19: 455 | T19: 50 | U19: 120 | V19: 53 | W19: 35 | X19: 110 | Y19: 87 | Z19: 14 | AA19: 7 | AB19: 9 | AC19: =SUM(Z19:AB19) -> 30 | AD19: B | AE19: Jugón | AF19: T | AH19: T | AI19: Patada ígnea | AJ19: Pat. S. Alta | AK19: Golpe bajo | AL19: Bote | AM19: Volador / Hada / Psíquico | AN19: Bicho / Siniestro / Roca | AO19: Volador / Hada / Psíquico | AP19: Bicho / Siniestro / Roca
A20: 244 | B20: Entei | C20: Johto | D20: Fire | F20: LEGEND | G20: L | H20: Entei | I20: 11 | J20: - | K20: Fully evolved | S20: 580 | T20: 115 | U20: 115 | V20: 85 | W20: 90 | X20: 75 | Y20: 100 | Z20: 18 | AA20: 9.5 | AB20: 10 | AC20: =SUM(Z20:AB20) -> 37.5 | AD20: S
A21: 141 | B21: Kabutops | C21: Kanto | D21: Rock | E21: Water | F21: NORMAL | G21: L | H21: Kabuto | I21: 21 | J21: Kabuto | K21: Fully evolved | S21: 495 | T21: 60 | U21: 115 | V21: 105 | W21: 65 | X21: 70 | Y21: 80 | Z21: 16 | AA21: 10.5 | AB21: 8 | AC21: =SUM(Z21:AB21) -> 34.5 | AD21: A | AE21: Poder antiguo | AF21: T | AH21: T | AI21: Acua jet | AJ21: Chupavidas | AK21: Poder pasado | AL21: Tierra viva | AM21: Tierra / Lucha / Eléctrico / Planta | AN21: Fuego / Hielo / Veneno / Volador / Normal | AO21: Tierra / Lucha / Eléctrico / Planta | AP21: Fuego / Hielo / Veneno / Volador / Normal
A22: 85 | B22: Dodrio | C22: Kanto | D22: Flying | E22: Normal | F22: NORMAL | G22: L | H22: Doduo | I22: 21 | J22: Doduo | K22: Fully evolved | S22: 460 | T22: 60 | U22: 110 | V22: 70 | W22: 60 | X22: 60 | Y22: 100 | Z22: 13 | AA22: 8.5 | AB22: 10 | AC22: =SUM(Z22:AB22) -> 31.5 | AD22: B | AE22: Ultra impulso | AF22: T | AH22: T | AI22: Pico taladro | AJ22: Triataque | AK22: Patada Salto | AL22: Persecución | AM22: Eléctrico / Hielo / Roca | AN22: Tierra / Fantasma / Bicho / Planta | AO22: Eléctrico / Hielo / Roca | AP22: Tierra / Fantasma / Bicho / Planta
A23: 59 | B23: Arcanine | C23: Kanto | D23: Fire | F23: NORMAL | G23: L | H23: Growlithe | I23: 21 | J23: Growlithe | K23: Fully evolved | S23: 555 | T23: 90 | U23: 110 | V23: 80 | W23: 100 | X23: 80 | Y23: 95 | Z23: 17 | AA23: 7.5 | AB23: 10 | AC23: =SUM(Z23:AB23) -> 34.5 | AD23: A | AE23: Policía | AF23: T | AH23: T | AI23: Colm. Rayo | AJ23: Envite ígneo | AK23: Vel. Extrema | AL23: Sol matinal | AM23: Tierra / Roca / Agua | AN23: Bicho / Fuego / Acero / Hielo / Planta / Hada | AO23: Tierra / Roca / Agua | AP23: Bicho / Fuego / Acero / Hielo / Planta / Hada
A24: 150 | B24: Mewtwo | C24: Kanto | D24: Psychic | F24: LEGEND | G24: L | H24: Mewtwo | I24: 11 | J24: - | K24: Fully evolved | S24: 680 | T24: 106 | U24: 110 | V24: 90 | W24: 154 | X24: 90 | Y24: 130 | Z24: 19 | AA24: 12 | AB24: 13 | AC24: =SUM(Z24:AB24) -> 44 | AD24: S | AE24: Clonación | AF24: T | AH24: T | AI24: Onda mental | AJ24: Rayo Hielo | AK24: Bola voltio | AL24: Esfera aural | AM24: Siniestro / Fantasma / Bicho | AN24: Psíquico / Lucha | AO24: Siniestro / Fantasma / Bicho | AP24: Psíquico / Lucha
A25: 123 | B25: Scyther | C25: Kanto | D25: Bug | E25: Flying | F25: NORMAL | G25: S | H25: Scyther | I25: 11 | J25: - | K25: Trading | S25: 500 | T25: 70 | U25: 110 | V25: 80 | W25: 55 | X25: 80 | Y25: 105 | Z25: 15 | AA25: 6 | AB25: 11 | AC25: =SUM(Z25:AB25) -> 32 | AD25: B | AE25: Vengador | AF25: C | AH25: C | AI25: Tijera X | AJ25: Tajo aéreo | AK25: Psicocorte | AL25: Tajo umbrío | AM25: Eléctrico / Fuego / Volador / Hielo / Roca | AN25: Tierra / Planta / Lucha / Bicho | AO25: Eléctrico / Fuego / Volador / Hielo / Roca | AP25: Tierra / Planta / Lucha / Bicho
A26: 143 | B26: Snorlax | C26: Kanto | D26: Normal | F26: NORMAL | G26: L | H26: Snorlax | I26: 11 | J26: - | K26: Fully evolved | S26: 540 | T26: 160 | U26: 110 | V26: 65 | W26: 65 | X26: 110 | Y26: 30 | Z26: 22 | AA26: 9.5 | AB26: 3 | AC26: =SUM(Z26:AB26) -> 34.5 | AD26: A | AE26: Remolón | AF26: T | AG26: Sonámbulo | AH26: C | AI26: Descanso | AJ26: Ronquido | AK26: Eructo | AL26: Giga impacto | AM26: Lucha | AN26: Fantasma | AO26: Lucha | AP26: Fantasma
A27: 142 | B27: Aerodactyl | C27: Kanto | D27: Rock | E27: Flying | F27: NORMAL | G27: L | H27: Aerodactyl | I27: 11 | J27: - | K27: Fully evolved | S27: 515 | T27: 80 | U27: 105 | V27: 65 | W27: 60 | X27: 75 | Y27: 130 | Z27: 15 | AA27: 7.5 | AB27: 13 | AC27: =SUM(Z27:AB27) -> 35.5 | AD27: A | AE27: Cazador primitivo | AF27: T | AH27: T | AI27: Ala bis | AJ27: Roca afilada | AK27: Hyperrayo | AL27: Llamarada | AM27: Hielo / Eléctrico / Roca / Acero / Agua | AN27: Tierra / Bicho / Veneno / Normal / Fuego / Volador | AO27: Hielo / Eléctrico / Roca / Acero / Agua | AP27: Tierra / Bicho / Veneno / Normal / Fuego / Volador
A28: 71 | B28: Victreebel | C28: Kanto | D28: Grass | E28: Poison | F28: NORMAL | G28: L | H28: Bellsprout | I28: 31 | J28: Weepinbell | K28: Fully evolved | S28: 490 | T28: 80 | U28: 105 | V28: 65 | W28: 100 | X28: 70 | Y28: 70 | Z28: 14 | AA28: 7 | AB28: 7 | AC28: =SUM(Z28:AB28) -> 28 | AD28: C | AE28: Atrapamoscas | AF28: T | AG28: Clorofila | AH28: C | AI28: Latigazo | AJ28: Bomba ácida | AK28: Estrujón | AL28: Golpe bajo | AM28: Fuego / Volador / Hielo / Psíquico | AN28: Planta / Hada / Lucha / Agua / Eléctrico | AO28: Fuego / Volador / Hielo / Psíquico | AP28: Planta / Hada / Lucha / Agua / Eléctrico
A29: 89 | B29: Muk | C29: Kanto | D29: Poison | F29: NORMAL | G29: L | H29: Grimer | I29: 21 | J29: Grimer | K29: Fully evolved | S29: 500 | T29: 105 | U29: 105 | V29: 75 | W29: 65 | X29: 100 | Y29: 50 | Z29: 19 | AA29: 6 | AB29: 5 | AC29: =SUM(Z29:AB29) -> 30 | AD29: B | AE29: Pestilente | AF29: T | AG29: Punto tóxico | AH29: C | AI29: Lanza mugre | AJ29: Llamarada | AK29: Sombra vil | AL29: Puño incremento | AM29: Tierra / Psíquico | AN29: Bicho / Lucha / Veneno / Planta / Hada | AO29: Tierra / Psíquico | AP29: Bicho / Lucha / Veneno / Planta / Hada
A30: 98 | B30: Krabby | C30: Kanto | D30: Water | F30: NORMAL | G30: S | H30: Krabby | I30: 11 | J30: - | K30: Candy | S30: 325 | T30: 30 | U30: 105 | V30: 90 | W30: 25 | X30: 25 | Y30: 50 | Z30: 10 | AA30: 5 | AB30: 5 | AC30: =SUM(Z30:AB30) -> 20 | AD30: D | AE30: Defensor | AF30: T | AH30: T | AI30: Agarre | AJ30: Concha filo | AK30: Demolición | AL30: Pataleta | AM30: Eléctrico / Planta | AN30: Agua / Acero / Fuego / Hielo | AO30: Eléctrico / Planta | AP30: Agua / Acero / Fuego / Hielo
A31: 57 | B31: Primeape | C31: Kanto | D31: Fighting | F31: NORMAL | G31: L | H31: Mankey | I31: 21 | J31: Mankey | K31: Fully evolved | S31: 455 | T31: 65 | U31: 105 | V31: 60 | W31: 60 | X31: 70 | Y31: 95 | Z31: 13 | AA31: 6 | AB31: 10 | AC31: =SUM(Z31:AB31) -> 29 | AD31: C | AE31: Cólera | AF31: C | AH31: C | AI31: Avalancha | AJ31: Demolición | AK31: Enfado | AL31: Sofoco | AM31: Volador / Hada / Psíquico | AN31: Bicho / Siniestro / Roca | AO31: Volador / Hada / Psíquico | AP31: Bicho / Siniestro / Roca
A32: 224 | B32: Octillery | C32: Johto | D32: Water | F32: NORMAL | G32: L | H32: Remoraid | I32: 21 | J32: Remoraid | K32: Fully evolved | S32: 480 | T32: 75 | U32: 105 | V32: 75 | W32: 105 | X32: 75 | Y32: 45 | Z32: 15 | AA32: 10.5 | AB32: 5 | AC32: =SUM(Z32:AB32) -> 30.5 | AD32: B
A33: 160 | B33: Feraligatr | C33: Johto | D33: Water | F33: STARTER | G33: L | H33: Totodile | I33: 31 | J33: Croconaw | K33: Fully evolved | S33: 530 | T33: 85 | U33: 105 | V33: 100 | W33: 79 | X33: 83 | Y33: 78 | Z33: 18 | AA33: 8.5 | AB33: 8 | AC33: =SUM(Z33:AB33) -> 34.5 | AD33: A
A34: 107 | B34: Hitmonchan | C34: Kanto | D34: Fighting | F34: NORMAL | G34: L | H34: Tyrogue | I34: 22 | J34: Tyrogue | K34: Fully evolved | R34: ATQ > SPD | S34: 455 | T34: 50 | U34: 105 | V34: 79 | W34: 35 | X34: 110 | Y34: 76 | Z34: 16 | AA34: 7 | AB34: 8 | AC34: =SUM(Z34:AB34) -> 31 | AD34: B | AE34: ¡Al ring! | AF34: T | AH34: T | AI34: Puño hielo | AJ34: Puño drenaje | AK34: Puño bala | AL34: Desarme | AM34: Volador / Hada / Psíquico | AN34: Bicho / Siniestro / Roca | AO34: Volador / Hada / Psíquico | AP34: Bicho / Siniestro / Roca
A35: 34 | B35: Nidoking | C35: Kanto | D35: Poison | E35: Ground | F35: NORMAL | G35: L | H35: Nidoran M | I35: 31 | J35: Nidorino | K35: Fully evolved | S35: 505 | T35: 81 | U35: 102 | V35: 77 | W35: 85 | X35: 75 | Y35: 85 | Z35: 16 | AA35: 7.5 | AB35: 9 | AC35: =SUM(Z35:AB35) -> 32.5 | AD35: B | AE35: Lealtad | AF35: C | AH35: C | AI35: Terremoto | AJ35: Lanzallamas | AK35: Rayo hielo | AL35: Rayo | AM35: Tierra / Hielo / Psíquico / Agua | AN35: Eléctrico / Veneno / Bicho / Hada / Lucha / Roca | AO35: Tierra / Hielo / Psíquico / Agua | AP35: Eléctrico / Veneno / Bicho / Hada / Lucha / Roca
A36: 251 | B36: Celebi | C36: Johto | D36: Psychic | E36: Grass | F36: NORMAL | G36: L | H36: Celebi | I36: 11 | J36: - | K36: Fully evolved | S36: 600 | T36: 100 | U36: 100 | V36: 100 | W36: 100 | X36: 100 | Y36: 100 | Z36: 20 | AA36: 9.5 | AB36: 10 | AC36: =SUM(Z36:AB36) -> 39.5 | AD36: S
A37: 67 | B37: Machoke | C37: Kanto | D37: Fighting | F37: NORMAL | G37: M | H37: Machop | I37: 21 | J37: Machop | K37: Trading | S37: 405 | T37: 80 | U37: 100 | V37: 70 | W37: 50 | X37: 60 | Y37: 45 | Z37: 14 | AA37: 6 | AB37: 5 | AC37: =SUM(Z37:AB37) -> 25 | AD37: D | AE37: Peleón | AF37: T | AH37: T | AI37: Tumba rocas | AJ37: Demolición | AK37: Puño hielo | AL37: Vendetta | AM37: Volador / Hada / Psíquico | AN37: Bicho / Siniestro / Roca | AO37: Volador / Hada / Psíquico | AP37: Bicho / Siniestro / Roca
A38: 151 | B38: Mew | C38: Kanto | D38: Psychic | F38: LEGEND | G38: L | H38: Mew | I38: 11 | J38: - | K38: Fully evolved | S38: 600 | T38: 100 | U38: 100 | V38: 100 | W38: 100 | X38: 100 | Y38: 100 | Z38: 20 | AA38: 9.5 | AB38: 10 | AC38: =SUM(Z38:AB38) -> 39.5 | AD38: S | AE38: Tinovictoria | AF38: T | AH38: T | AI38: Psíquico | AJ38: Fitoimpulso | AK38: Poltergeist | AL38: Esfera aural | AM38: Siniestro / Fantasma / Bicho | AN38: Psíquico / Lucha | AO38: Siniestro / Fantasma / Bicho | AP38: Psíquico / Lucha
A39: 146 | B39: Moltres | C39: Kanto | D39: Fire | E39: Flying | F39: LEGEND | G39: L | H39: Moltres | I39: 11 | J39: - | K39: Fully evolved | S39: 580 | T39: 90 | U39: 100 | V39: 90 | W39: 125 | X39: 85 | Y39: 90 | Z39: 18 | AA39: 10.5 | AB39: 9 | AC39: =SUM(Z39:AB39) -> 37.5 | AD39: S | AE39: Restauración | AF39: T | AH39: T | AI39: Ataque aéreo | AJ39: Llamarada | AK39: Rayo solar | AL39: Arenas ardientes | AM39: Eléctrico / Roca / Agua | AN39: Tierra / Bicho / Planta / Hada / Lucha / Fuego / Acero | AO39: Eléctrico / Roca / Agua | AP39: Tierra / Bicho / Planta / Hada / Lucha / Fuego / Acero
A40: 78 | B40: Rapidash | C40: Kanto | D40: Fire | F40: NORMAL | G40: L | H40: Ponyta | I40: 21 | J40: Ponyta | K40: Fully evolved | S40: 500 | T40: 65 | U40: 100 | V40: 70 | W40: 80 | X40: 80 | Y40: 105 | Z40: 14 | AA40: 7.5 | AB40: 11 | AC40: =SUM(Z40:AB40) -> 32.5 | AD40: B | AE40: Ultra impulso | AF40: T | AH40: T | AI40: Bote | AJ40: Llamarada | AK40: Hypnosis | AL40: Fuerza equina | AM40: Tierra / Roca / Agua | AN40: Bicho / Fuego / Acero / Hielo / Planta / Hada | AO40: Tierra / Roca / Agua | AP40: Bicho / Fuego / Acero / Hielo / Planta / Hada
...

Sheet Analisis lideres
B2: PKMN | C2: HP | D2: ATT | E2: SPD | F2: ALL | G2: SUM
B3: Sandshrew de Brock | C3: 11 | D3: 4 | E3: 4 | F3: =SUM(C3:E3) -> 19 | G3: =SUM(F3:F4) -> 48
B4: Onix de Brock | C4: 16 | D4: 6 | E4: 7 | F4: =SUM(C4:E4) -> 29
B5: Psyduck de Misty | C5: 9.8666667 | D5: 4 | E5: 5.5 | F5: =SUM(C5:E5) -> 19.366667 | G5: =SUM(F5:F6) -> 55.2
B6: Starmie de Misty | C6: 15.333333 | D6: 9 | E6: 11.5 | F6: =SUM(C6:E6) -> 35.833333
B7: Raichu de Lt Surge | C7: 13 | D7: 8 | E7: 11 | F7: =SUM(C7:E7) -> 32 | G7: =SUM(F7:F8) -> 64.3
B8: Electabuzz de Lt Surge | C8: 13.8 | D8: 8 | E8: 10.5 | F8: =SUM(C8:E8) -> 32.3
B9: Parasect de Erika | C9: 14.666667 | D9: 6 | E9: 3 | F9: =SUM(C9:E9) -> 23.666667 | G9: =SUM(F9:F10) -> 53.333333
B10: Vileplume de Erika | C10: 16.666667 | D10: 8 | E10: 5 | F10: =SUM(C10:E10) -> 29.666667
B11: Jynx de Sabrina | C11: 13 | D11: 7 | E11: 9.5 | F11: =SUM(C11:E11) -> 29.5 | G11: =SUM(F11:F12) -> 63.5
B12: Alakazam de Sabrina | C12: 13 | D12: 9 | E12: 12 | F12: =SUM(C12:E12) -> 34
B13: Arbok de Koga | C13: 13.866667 | D13: 8 | E13: 8 | F13: =SUM(C13:E13) -> 29.866667 | G13: =SUM(F13:F14) -> 56.533333
B14: Venomoth de Koga | C14: 13.666667 | D14: 4 | E14: 9 | F14: =SUM(C14:E14) -> 26.666667
B15: Arcanine de Blaine | C15: 16.666667 | D15: 8 | E15: 9.5 | F15: =SUM(C15:E15) -> 34.166667 | G15: =SUM(F15:F16) -> 66.266667
B16: Magmar de Blaine | C16: 13.8 | D16: 9 | E16: 9.3 | F16: =SUM(C16:E16) -> 32.1
B17: Rhydon de Giovanni | C17: 18 | D17: 8 | E17: 4 | F17: 30 | G17: =SUM(F17:F18) -> 67.666667
B18: Kangaskhan de Giovanni | C18: 17.666667 | D18: 11 | E18: 9 | F18: =SUM(C18:E18) -> 37.666667
B21: PKMN | C21: HP | D21: ATT | E21: SPD | F21: ALL | G21: SUM
B22: Gengar | C22: 13 | D22: 9 | E22: 11 | F22: =SUM(C22:E22) -> 33 | G22: =SUM(F22:F24) -> 94.866667
B23: Hypno | C23: 18 | D23: 8 | E23: 6.7 | F23: =SUM(C23:E23) -> 32.7
B24: Marowak | C24: 16.666667 | D24: 8 | E24: 4.5 | F24: =SUM(C24:E24) -> 29.166667
B25: Machamp | C25: 17 | D25: 8 | E25: 5.5 | F25: =SUM(C25:E25) -> 30.5 | G25: =SUM(F25:F27) -> 90.933333
B26: Hitmonlee | C26: 14.2 | D26: 7 | E26: 8.7 | F26: =SUM(C26:E26) -> 29.9
B27: Hitmonchan | C27: 15.933333 | D27: 7 | E27: 7.6 | F27: =SUM(C27:E27) -> 30.533333
B28: Charizard | C28: 16.066667 | D28: 8 | E28: 10 | F28: =SUM(C28:E28) -> 34.066667 | G28: =SUM(F28:F30) -> 106.8
B29: Aerodactyl | C29: 14.666667 | D29: 8 | E29: 13 | F29: =SUM(C29:E29) -> 35.666667
B30: Dragonite | C30: 19.066667 | D30: 10 | E30: 8 | F30: =SUM(C30:E30) -> 37.066667
B31: Cloyster | C31: 18.333333 | D31: 7 | E31: 7 | F31: =SUM(C31:E31) -> 32.333333 | G31: =SUM(F31:F33) -> 96.5
B32: Exeggutor | C32: 16.333333 | D32: 8 | E32: 5.5 | F32: =SUM(C32:E32) -> 29.833333
B33: Lapras | C33: 20.333333 | D33: 8 | E33: 6 | F33: =SUM(C33:E33) -> 34.333333
F35: =SUM(F22:F33)/3 -> 129.7

Sheet Pokemon Data
A1: Real Games
A2: Basic | M2: Evolution | P2: Original stats
A3: # | B3: Name | C3: Cod | D3: Male | E3: Female | F3: Egg | G3: Generation | H3: Type 1 | I3: Type 2 | J3: TAG | K3: Rarity | L3: Family | M3: Preevolution | N3: Stage | O3: Method | P3: Total | Q3: HP | R3: Attack | S3: Defense | T3: Sp. Atk | U3: Sp. Def
A4: 1 | B4: Bulbasaur | C4: 0001A0 | D4: 0.85 | E4: 0.15 | F4: Grass | G4: Kanto | H4: Grass | I4: Poison | J4: Starter | K4: Rare | L4: 0001A0 | M4: - | N4: Basic | O4: - | P4: 318 | Q4: 45 | R4: 49 | S4: 49 | T4: 65 | U4: 65 | V4: 45
A5: 2 | B5: Ivysaur | C5: 0002A0 | D5: 0.85 | E5: 0.15 | F5: Grass | G5: Kanto | H5: Grass | I5: Poison | J5: Starter | K5: Rare | L5: 0001A0 | M5: 0001A0 | N5: Middle | O5: Experience | P5: 405 | Q5: 60 | R5: 62 | S5: 63 | T5: 80 | U5: 80 | V5: 60
A6: 3 | B6: Venusaur | C6: 0003A0 | D6: 0.85 | E6: 0.15 | F6: Grass | G6: Kanto | H6: Grass | I6: Poison | J6: Starter | K6: Rare | L6: 0001A0 | M6: 0002A0 | N6: Final | O6: Experience | P6: 525 | Q6: 80 | R6: 82 | S6: 83 | T6: 100 | U6: 100 | V6: 80
A7: 3 | B7: Venusaur (Mega Venusaur) | C7: 0003M0 | D7: 0.85 | E7: 0.15 | F7: Grass | G7: Kanto | H7: Grass | I7: Poison | J7: Mega | K7: Non available | L7: 0001A0 | M7: 0003A0 | N7: Mega | O7: Megastone | P7: 625 | Q7: 80 | R7: 100 | S7: 123 | T7: 122 | U7: 120 | V7: 80
A8: 4 | B8: Charmander | C8: 0004A0 | D8: 0.85 | E8: 0.15 | F8: Dragon | G8: Kanto | H8: Fire | I8: - | J8: Starter | K8: Rare | L8: 0004A0 | M8: - | N8: Basic | O8: - | P8: 309 | Q8: 39 | R8: 52 | S8: 43 | T8: 60 | U8: 50 | V8: 65
A9: 5 | B9: Charmeleon | C9: 0005A0 | D9: 0.85 | E9: 0.15 | F9: Dragon | G9: Kanto | H9: Fire | I9: - | J9: Starter | K9: Rare | L9: 0004A0 | M9: 0004A0 | N9: Middle | O9: Experience | P9: 405 | Q9: 58 | R9: 64 | S9: 58 | T9: 80 | U9: 65 | V9: 80
A10: 6 | B10: Charizard | C10: 0006A0 | D10: 0.85 | E10: 0.15 | F10: Dragon | G10: Kanto | H10: Fire | I10: Flying | J10: Starter | K10: Rare | L10: 0004A0 | M10: 0005A0 | N10: Final | O10: Experience | P10: 534 | Q10: 78 | R10: 84 | S10: 78 | T10: 109 | U10: 85 | V10: 100
A11: 6 | B11: Charizard (Mega Charizard X) | C11: 0006M0 | D11: 0.85 | E11: 0.15 | F11: Dragon | G11: Kanto | H11: Fire | I11: Dragon | J11: Mega | K11: Non available | L11: 0004A0 | M11: 0006A0 | N11: Mega | O11: Megastone | P11: 634 | Q11: 78 | R11: 130 | S11: 111 | T11: 130 | U11: 85 | V11: 100
A12: 6 | B12: Charizard (Mega Charizard Y) | C12: 0006N0 | D12: 0.85 | E12: 0.15 | F12: Dragon | G12: Kanto | H12: Fire | I12: Flying | J12: Mega | K12: Non available | L12: 0004A0 | M12: 0006A0 | N12: Mega | O12: Megastone | P12: 634 | Q12: 78 | R12: 104 | S12: 78 | T12: 159 | U12: 115 | V12: 100
A13: 7 | B13: Squirtle | C13: 0007A0 | D13: 0.85 | E13: 0.15 | F13: Water 1 | G13: Kanto | H13: Water | I13: - | J13: Starter | K13: Rare | L13: 0007A0 | M13: - | N13: Basic | O13: - | P13: 314 | Q13: 44 | R13: 48 | S13: 65 | T13: 50 | U13: 64 | V13: 43
A14: 8 | B14: Wartortle | C14: 0008A0 | D14: 0.85 | E14: 0.15 | F14: Water 1 | G14: Kanto | H14: Water | I14: - | J14: Starter | K14: Rare | L14: 0007A0 | M14: 0007A0 | N14: Middle | O14: Experience | P14: 405 | Q14: 59 | R14: 63 | S14: 80 | T14: 65 | U14: 80 | V14: 58
A15: 9 | B15: Blastoise | C15: 0009A0 | D15: 0.85 | E15: 0.15 | F15: Water 1 | G15: Kanto | H15: Water | I15: - | J15: Starter | K15: Rare | L15: 0007A0 | M15: 0008A0 | N15: Final | O15: Experience | P15: 530 | Q15: 79 | R15: 83 | S15: 100 | T15: 85 | U15: 105 | V15: 78
... A114: 80 | B114: Slowbro (Mega Slowbro) | C114: 0080M0 | D114: 0.5 | E114: 0.5 | F114: Water 1 | G114: Kanto | H114: Water | I114: Psychic | J114: Mega | K114: Non available | L114: 0079A0 | M114: 0080A0 | N114: Mega | O114: Megastone | P114: 590 | Q114: 95 | R114: 75 | S114: 180 | T114: 130 | U114: 80 | V114: 30
A115: 81 | B115: Magnemite | C115: 0081A0 | D115: - | E115: - | F115: Mineral | G115: Kanto | H115: Electric | I115: Steel | J115: Basic | K115: Common | L115: 0081A0 | M115: - | N115: Basic | O115: - | P115: 325 | Q115: 25 | R115: 35 | S115: 70 | T115: 95 | U115: 55 | V115: 45
A116: 82 | B116: Magneton | C116: 0082A0 | D116: - | E116: - | F116: Mineral | G116: Kanto | H116: Electric | I116: Steel | J116: Basic | K116: Common | L116: 0081A0 | M116: 0081A0 | N116: Middle | O116: Experience | P116: 465 | Q116: 50 | R116: 60 | S116: 95 | T116: 120 | U116: 70 | V116: 70
A117: 83 | B117: Farfetch'd | C117: 0083A0 | D117: 0.5 | E117: 0.5 | F117: Flying | G117: Kanto | H117: Flying | I117: Normal | J117: Basic | K117: Uncommon | L117: 0083A0 | M117: - | N117: Final | O117: - | P117: 377 | Q117: 52 | R117: 90 | S117: 55 | T117: 58 | U117: 62 | V117: 60
A118: 83 | B118: Farfetch'd (Galarian Form) | C118: 0083G0 | D118: 0.5 | E118: 0.5 | F118: Flying | G118: Galar | H118: Fighting | I118: - | J118: Basic | K118: Uncommon | L118: 0083A0 | M118: - | N118: Basic | O118: - | P118: 377 | Q118: 52 | R118: 95 | S118: 55 | T118: 58 | U118: 62 | V118: 55
A119: 84 | B119: Doduo | C119: 0084A0 | D119: 0.5 | E119: 0.5 | F119: Flying | G119: Kanto | H119: Flying | I119: Normal | J119: Basic | K119: Uncommon | L119: 0084A0 | M119: - | N119: Basic | O119: - | P119: 310 | Q119: 35 | R119: 85 | S119: 45 | T119: 35 | U119: 35 | V119: 75
A120: 85 | B120: Dodrio | C120: 0085A0 | D120: 0.5 | E120: 0.5 | F120: Flying | G120: Kanto | H120: Flying | I120: Normal | J120: Basic | K120: Uncommon | L120: 0084A0 | M120: 0084A0 | N120: Final | O120: Experience | P120: 470 | Q120: 60 | R120: 110 | S120: 70 | T120: 60 | U120: 60 | V120: 110
A121: 86 | B121: Seel | C121: 0086A0 | D121: 0.5 | E121: 0.5 | F121: Water 3 | G121: Kanto | H121: Water | I121: - | J121: Basic | K121: Uncommon | L121: 0086A0 | M121: - | N121: Basic | O121: - | P121: 325 | Q121: 65 | R121: 45 | S121: 55 | T121: 45 | U121: 70 | V121: 45
A122: 87 | B122: Dewgong | C122: 0087A0 | D122: 0.5 | E122: 0.5 | F122: Water 3 | G122: Kanto | H122: Water | I122: Ice | J122: Basic | K122: Uncommon | L122: 0086A0 | M122: 0086A0 | N122: Final | O122: Experience | P122: 475 | Q122: 90 | R122: 70 | S122: 80 | T122: 70 | U122: 95 | V122: 70
A123: 88 | B123: Grimer | C123: 0088A0 | D123: 0.5 | E123: 0.5 | F123: Amorphous | G123: Kanto | H123: Poison | I123: - | J123: Basic | K123: Uncommon | L123: 0088A0 | M123: - | N123: Basic | O123: - | P123: 325 | Q123: 80 | R123: 80 | S123: 50 | T123: 40 | U123: 50 | V123: 25
A124: 88 | B124: Grimer (Alolan Form) | C124: 0088L0 | D124: 0.5 | E124: 0.5 | F124: Amorphous | G124: Alola | H124: Poison | I124: Dark | J124: Basic | K124: Uncommon | L124: 0088A0 | M124: - | N124: Basic | O124: - | P124: 325 | Q124: 80 | R124: 80 | S124: 50 | T124: 40 | U124: 50 | V124: 25
A125: 89 | B125: Muk | C125: 0089A0 | D125: 0.5 | E125: 0.5 | F125: Amorphous | G125: Kanto | H125: Poison | I125: - | J125: Basic | K125: Uncommon | L125: 0088A0 | M125: 0088A0 | N125: Final | O125: Experience | P125: 500 | Q125: 105 | R125: 105 | S125: 75 | T125: 65 | U125: 100 | V125: 50
A126: 89 | B126: Muk (Alolan Form) | C126: 0089L0 | D126: 0.5 | E126: 0.5 | F126: Amorphous | G126: Alola | H126: Poison | I126: Dark | J126: Basic | K126: Uncommon | L126: 0088A0 | M126: 0088L0 | N126: Final | O126: Experience | P126: 500 | Q126: 105 | R126: 105 | S126: 75 | T126: 65 | U126: 100 | V126: 50
A127: 90 | B127: Shellder | C127: 0090A0 | D127: 0.5 | E127: 0.5 | F127: Water 3 | G127: Kanto | H127: Water | I127: - | J127: Basic | K127: Uncommon | L127: 0090A0 | M127: - | N127: Basic | O127: - | P127: 305 | Q127: 30 | R127: 65 | S127: 100 | T127: 45 | U127: 25 | V127: 40
A128: 91 | B128: Cloyster | C128: 0091A0 | D128: 0.5 | E128: 0.5 | F128: Water 2 | G128: Kanto | H128: Water | I128: Ice | J128: Basic | K128: Uncommon | L128: 0090A0 | M128: 0090A0 | N128: Final | O128: Stone | P128: 525 | Q128: 50 | R128: 95 | S128: 180 | T128: 85 | U128: 45 | V128: 70
... A137: 99 | B137: Kingler | C137: 0099A0 | D137: 0.5 | E137: 0.5 | F137: Water 3 | G137: Kanto | H137: Water | I137: - | J137: Basic | K137: Common | L137: 0098A0 | M137: 0098A0 | N137: Final | O137: Experience | P137: 475 | Q137: 55 | R137: 130 | S137: 115 | T137: 50 | U137: 50 | V137: 75
A138: 100 | B138: Voltorb | C138: 0100A0 | D138: - | E138: - | F138: Mineral | G138: Kanto | H138: Electric | I138: - | J138: Basic | K138: Common | L138: 0100A0 | M138: - | N138: Basic | O138: - | P138: 330 | Q138: 40 | R138: 30 | S138: 50 | T138: 55 | U138: 55 | V138: 100
A139: 100 | B139: Voltorb (Hisuian Voltorb) | C139: 0100H0 | D139: 0.5 | E139: 0.5 | F139: Mineral | G139: Hisui | H139: Electric | I139: Grass | J139: Basic | K139: Common | L139: 0100A0 | M139: - | N139: Basic | O139: - | P139: 330 | Q139: 40 | R139: 30 | S139: 50 | T139: 55 | U139: 55 | V139: 100
A140: 101 | B140: Electrode | C140: 0101A0 | D140: - | E140: - | F140: Mineral | G140: Kanto | H140: Electric | I140: - | J140: Basic | K140: Common | L140: 0100A0 | M140: 0100A0 | N140: Final | O140: Experience | P140: 490 | Q140: 60 | R140: 50 | S140: 70 | T140: 80 | U140: 80 | V140: 150
A141: 101 | B141: Electrode (Hisuian Electrode) | C141: 0101H0 | D141: 0.5 | E141: 0.5 | F141: Mineral | G141: Hisui | H141: Electric | I141: Gr | J141: Basic | K141: Common | L141: 0100A0 | M141: 0100H0 | N141: Final | O141: Experience | P141: 490 | Q141: 60 | R141: 50 | S141: 70 | T141: 80 | U141: 80 | V141: 150
A142: 102 | B142: Exeggcute | C142: 0102A0 | D142: 0.5 | E142: 0.5 | F142: Grass | G142: Kanto | H142: Grass | I142: Psychic | J142: Basic | K142: Uncommon | L142: 0102A0 | M142: - | N142: Basic | O142: - | P142: 325 | Q142: 60 | R142: 40 | S142: 80 | T142: 60 | U142: 45 | V142: 40
A143: 103 | B143: Exeggutor | C143: 0103A0 | D143: 0.5 | E143: 0.5 | F143: Grass | G143: Kanto | H143: Grass | I143: Psychic | J143: Basic | K143: Uncommon | L143: 0102A0 | M143: 0102A0 | N143: Final | O143: Stone | P143: 530 | Q143: 95 | R143: 95 | S143: 85 | T143: 125 | U143: 75 | V143: 55
A144: 103 | B144: Exeggutor (Alolan Form) | C144: 0103L0 | D144: 0.5 | E144: 0.5 | F144: Grass | G144: Alola | H144: Grass | I144: Dragon | J144: Basic | K144: Uncommon | L144: 0102A0 | M144: 0102A0 | N144: Final | O144: Stone | P144: 530 | Q144: 95 | R144: 105 | S144: 85 | T144: 125 | U144: 75 | V144: 45
A145: 104 | B145: Cubone | C145: 0104A0 | D145: 0.5 | E145: 0.5 | F145: Monster | G145: Kanto | H145: Ground | I145: - | J145: Basic | K145: Uncommon | L145: 0104A0 | M145: - | N145: Basic | O145: - | P145: 320 | Q145: 50 | R145: 50 | S145: 95 | T145: 40 | U145: 50 | V145: 35
A146: 105 | B146: Marowak | C146: 0105A0 | D146: 0.5 | E146: 0.5 | F146: Monster | G146: Kanto | H146: Ground | I146: - | J146: Basic | K146: Uncommon | L146: 0104A0 | M146: 0104A0 | N146: Final | O146: Experience | P146: 425 | Q146: 60 | R146: 80 | S146: 110 | T146: 50 | U146: 80 | V146: 45
...

Sheet Hatch
A1: Basic | M1: Evolution | AC1: Original stats
A2: # | B2: Name | C2: Cod | D2: Male | E2: Female | F2: Egg | G2: Generation | H2: Type 1 | I2: Type 2 | J2: TAG | K2: Rarity | L2: Family | M2: Preevolution | N2: Stage | O2: Desgaste | P2: Method | Q2: edadMinima | R2: minStyle | S2: minIQ | T2: minKindness | U2: minStrength | V2: itemNecesario | W2: statSosten | X2: minSosten | Y2: percentSosten | Z2: horasSosten | AA2: Acción | AB2: Repetición | AC2: Total | AD2: HP | AE2: Attack | AF2: Defense | AG2: Sp. Atk | AH2: Sp. Def | AI2: Speed
A3: 1 | B3: Bulbasaur | C3: 0001A0 | D3: 0.85 | E3: 0.15 | F3: Grass | G3: Kanto | H3: Grass | I3: Poison | J3: Starter | K3: 4 | L3: 0001A0 | M3: - | N3: Kid | O3: 1.75 | P3: - | AC3: 318 | AD3: 45 | AE3: 49 | AF3: 49 | AG3: 65 | AH3: 65 | AI3: 45
A4: 2 | B4: Ivysaur | C4: 0002A0 | D4: 0.85 | E4: 0.15 | F4: Grass | G4: Kanto | H4: Grass | I4: Poison | J4: Starter | K4: 4 | L4: 0001A0 | M4: 0001A0 | N4: Teen | O4: 1.75 | P4: Experience | AC4: 405 | AD4: 60 | AE4: 62 | AF4: 63 | AG4: 80 | AH4: 80 | AI4: 60
A5: 3 | B5: Venusaur | C5: 0003A0 | D5: 0.85 | E5: 0.15 | F5: Grass | G5: Kanto | H5: Grass | I5: Poison | J5: Starter | K5: 4 | L5: 0001A0 | M5: 0002A0 | N5: Adult | O5: 1.75 | P5: Experience | AC5: 525 | AD5: 80 | AE5: 82 | AF5: 83 | AG5: 100 | AH5: 100 | AI5: 80
A6: 4 | B6: Charmander | C6: 0004A0 | D6: 0.85 | E6: 0.15 | F6: Dragon | G6: Kanto | H6: Fire | I6: - | J6: Starter | K6: 4 | L6: 0004A0 | M6: - | N6: Kid | O6: 1.75 | P6: - | AC6: 309 | AD6: 39 | AE6: 52 | AF6: 43 | AG6: 60 | AH6: 50 | AI6: 65
A7: 5 | B7: Charmeleon | C7: 0005A0 | D7: 0.85 | E7: 0.15 | F7: Dragon | G7: Kanto | H7: Fire | I7: - | J7: Starter | K7: 4 | L7: 0004A0 | M7: 0004A0 | N7: Teen | O7: 1.75 | P7: Experience | AC7: 405 | AD7: 58 | AE7: 64 | AF7: 58 | AG7: 80 | AH7: 65 | AI7: 80
A8: 6 | B8: Charizard | C8: 0006A0 | D8: 0.85 | E8: 0.15 | F8: Dragon | G8: Kanto | H8: Fire | I8: Flying | J8: Starter | K8: 4 | L8: 0004A0 | M8: 0005A0 | N8: Adult | O8: 1.75 | P8: Experience | AC8: 534 | AD8: 78 | AE8: 84 | AF8: 78 | AG8: 109 | AH8: 85 | AI8: 100
A9: 7 | B9: Squirtle | C9: 0007A0 | D9: 0.85 | E9: 0.15 | F9: Water 1 | G9: Kanto | H9: Water | I9: - | J9: Starter | K9: 4 | L9: 0007A0 | M9: - | N9: Kid | O9: 1.75 | P9: - | AC9: 314 | AD9: 44 | AE9: 48 | AF9: 65 | AG9: 50 | AH9: 64 | AI9: 43
A10: 8 | B10: Wartortle | C10: 0008A0 | D10: 0.85 | E10: 0.15 | F10: Water 1 | G10: Kanto | H10: Water | I10: - | J10: Starter | K10: 4 | L10: 0007A0 | M10: 0007A0 | N10: Teen | O10: 1.75 | P10: Experience | AC10: 405 | AD10: 59 | AE10: 63 | AF10: 80 | AG10: 65 | AH10: 80 | AI10: 58
A11: 9 | B11: Blastoise | C11: 0009A0 | D11: 0.85 | E11: 0.15 | F11: Water 1 | G11: Kanto | H11: Water | I11: - | J11: Starter | K11: 4 | L11: 0007A0 | M11: 0008A0 | N11: Adult | O11: 1.75 | P11: Experience | AC11: 530 | AD11: 79 | AE11: 83 | AF11: 100 | AG11: 85 | AH11: 105 | AI11: 78
A12: 10 | B12: Caterpie | C12: 0010A0 | D12: 0.5 | E12: 0.5 | F12: Bug | G12: Kanto | H12: Bug | I12: - | J12: Basic | K12: 1 | L12: 0010A0 | M12: - | N12: Kid | O12: 1 | P12: - | AC12: 195 | AD12: 45 | AE12: 30 | AF12: 35 | AG12: 20 | AH12: 20 | AI12: 45
A13: 11 | B13: Metapod | C13: 0011A0 | D13: 0.5 | E13: 0.5 | F13: Bug | G13: Kanto | H13: Bug | I13: - | J13: Basic | K13: 1 | L13: 0010A0 | M13: 0010A0 | N13: Teen | O13: 1 | P13: Experience | AC13: 205 | AD13: 50 | AE13: 20 | AF13: 55 | AG13: 25 | AH13: 25 | AI13: 30
A14: 12 | B14: Butterfree | C14: 0012A0 | D14: 0.5 | E14: 0.5 | F14: Bug | G14: Kanto | H14: Bug | I14: Flying | J14: Basic | K14: 1 | L14: 0010A0 | M14: 0011A0 | N14: Adult | O14: 1 | P14: Experience | AC14: 395 | AD14: 60 | AE14: 45 | AF14: 50 | AG14: 90 | AH14: 80 | AI14: 70
... A28: 24 | B28: Arbok | C28: 0024A0 | D28: 0.5 | E28: 0.5 | F28: Field | G28: Kanto | H28: Poison | I28: - | J28: Basic | K28: 1 | L28: 0023A0 | M28: 0023A0 | N28: Adult | O28: 1 | P28: Experience | AC28: 448 | AD28: 60 | AE28: 95 | AF28: 69 | AG28: 65 | AH28: 79 | AI28: 80
A29: 25 | B29: Pikachu | C29: 0025A0 | D29: 0.5 | E29: 0.5 | F29: Fairy | G29: Kanto | H29: Electric | I29: - | J29: Basic | K29: 2 | L29: 0172A0 | M29: 0172A0 | N29: Kid | O29: 1.25 | P29: Experience | Q29: 1 | W29: felicidad | Y29: 70 | Z29: 6 | AC29: 320 | AD29: 35 | AE29: 55 | AF29: 40 | AG29: 50 | AH29: 50 | AI29: 90
A30: 26 | B30: Raichu | C30: 0026A0 | D30: 0.5 | E30: 0.5 | F30: Fairy | G30: Kanto | H30: Electric | I30: - | J30: Basic | K30: 2 | L30: 0172A0 | M30: 0025A0 | N30: Adult | O30: 1.25 | P30: Stone | Q30: 2 | V30: piedra_trueno | AC30: 485 | AD30: 60 | AE30: 90 | AF30: 55 | AG30: 90 | AH30: 80 | AI30: 110
A31: 26 | B31: Raichu (Alolan Form) | C31: 0026L0 | D31: 0.5 | E31: 0.5 | F31: Fairy | G31: Alola | H31: Electric | I31: Psychic | J31: Basic | K31: 2 | L31: 0172A0 | M31: 0025A0 | N31: Adult | O31: 1.25 | P31: Stone | Q31: 2 | R31: 80 | AC31: 485 | AD31: 60 | AE31: 85 | AF31: 50 | AG31: 95 | AH31: 85 | AI31: 110
A32: 27 | B32: Sandshrew | C32: 0027A0 | D32: 0.5 | E32: 0.5 | F32: Field | G32: Kanto | H32: Ground | I32: - | J32: Basic | K32: 2 | L32: 0027A0 | M32: - | N32: Kid | O32: 1.25 | P32: - | AC32: 300 | AD32: 50 | AE32: 75 | AF32: 85 | AG32: 20 | AH32: 30 | AI32: 40
A33: 27 | B33: Sandshrew (Alolan Form) | C33: 0027L0 | D33: 0.5 | E33: 0.5 | F33: Field | G33: Alola | H33: Ice | I33: Steel | J33: Basic | K33: 2 | L33: 0027A0 | M33: - | N33: Kid | O33: 1.25 | P33: - | AC33: 300 | AD33: 50 | AE33: 75 | AF33: 90 | AG33: 10 | AH33: 35 | AI33: 40
A34: 28 | B34: Sandslash | C34: 0028A0 | D34: 0.5 | E34: 0.5 | F34: Field | G34: Kanto | H34: Ground | I34: - | J34: Basic | K34: 2 | L34: 0027A0 | M34: 0027A0 | N34: Adult | O34: 1.25 | P34: Experience | AC34: 450 | AD34: 75 | AE34: 100 | AF34: 110 | AG34: 45 | AH34: 55 | AI34: 65
A35: 28 | B35: Sandslash (Alolan Form) | C35: 0028L0 | D35: 0.5 | E35: 0.5 | F35: Field | G35: Alola | H35: Ice | I35: Steel | J35: Basic | K35: 2 | L35: 0027A0 | M35: 0027L0 | N35: Adult | O35: 1.25 | P35: Experience | AC35: 450 | AD35: 75 | AE35: 100 | AF35: 120 | AG35: 25 | AH35: 65 | AI35: 65
A36: 29 | B36: Nidoran♀ | C36: 0029A0 | D36: 0 | E36: 1 | F36: Field | G36: Kanto | H36: Poison | I36: - | J36: Basic | K36: 1 | L36: 0029A0 | M36: - | N36: Kid | O36: 1 | P36: - | AC36: 275 | AD36: 55 | AE36: 47 | AF36: 52 | AG36: 40 | AH36: 40 | AI36: 41
A37: 30 | B37: Nidorina | C37: 0030A0 | D37: 0 | E37: 1 | F37: Undiscovered | G37: Kanto | H37: Poison | I37: - | J37: Basic | K37: 1 | L37: 0029A0 | M37: 0029A0 | N37: Teen | O37: 1 | P37: Experience | AC37: 365 | AD37: 70 | AE37: 62 | AF37: 67 | AG37: 55 | AH37: 55 | AI37: 56
A38: 31 | B38: Nidoqueen | C38: 0031A0 | D38: 0 | E38: 1 | F38: Undiscovered | G38: Kanto | H38: Poison | I38: Ground | J38: Basic | K38: 1 | L38: 0029A0 | M38: 0030A0 | N38: Adult | O38: 1 | P38: Stone | AC38: 505 | AD38: 90 | AE38: 92 | AF38: 87 | AG38: 75 | AH38: 85 | AI38: 76
A39: 32 | B39: Nidoran♂ | C39: 0032A0 | D39: 1 | E39: 0 | F39: Field | G39: Kanto | H39: Poison | I39: - | J39: Basic | K39: 1 | L39: 0032A0 | M39: - | N39: Kid | O39: 1 | P39: - | AC39: 273 | AD39: 46 | AE39: 57 | AF39: 40 | AG39: 40 | AH39: 40 | AI39: 50
A40: 33 | B40: Nidorino | C40: 0033A0 | D40: 1 | E40: 0 | F40: Field | G40: Kanto | H40: Poison | I40: - | J40: Basic | K40: 1 | L40: 0032A0 | M40: 0032A0 | N40: Teen | O40: 1 | P40: Experience | AC40: 365 | AD40: 61 | AE40: 72 | AF40: 57 | AG40: 55 | AH40: 55 | AI40: 65
A41: 34 | B41: Nidoking | C41: 0034A0 | D41: 1 | E41: 0 | F41: Field | G41: Kanto | H41: Poison | I41: Ground | J41: Basic | K41: 1 | L41: 0032A0 | M41: 0033A0 | N41: Adult | O41: 1 | P41: Stone | AC41: 505 | AD41: 81 | AE41: 102 | AF41: 77 | AG41: 85 | AH41: 75 | AI41: 85
A42: 35 | B42: Clefairy | C42: 0035A0 | D42: 0.25 | E42: 0.75 | F42: Fairy | G42: Kanto | H42: Fairy | I42: - | J42: Basic | K42: 2 | L42: 0173A0 | M42: 0173A0 | N42: Kid | O42: 1.25 | P42: Experience | Q42: 1 | W42: felicidad | Y42: 70 | Z42: 6 | AC42: 323 | AD42: 70 | AE42: 45 | AF42: 48 | AG42: 60 | AH42: 65 | AI42: 35
A43: 36 | B43: Clefable | C43: 0036A0 | D43: 0.25 | E43: 0.75 | F43: Fairy | G43: Kanto | H43: Fairy | I43: - | J43: Basic | K43: 2 | L43: 0173A0 | M43: 0035A0 | N43: Adult | O43: 1.25 | P43: Stone | Q43: 2 | V43: piedra_lunar | AC43: 483 | AD43: 95 | AE43: 70 | AF43: 73 | AG43: 95 | AH43: 90 | AI43: 60
A44: 37 | B44: Vulpix | C44: 0037A0 | D44: 0.25 | E44: 0.75 | F44: Field | G44: Kanto | H44: Fire | I44: - | J44: Basic | K44: 2 | L44: 0037A0 | M44: - | N44: Kid | O44: 1.25 | P44: - | AC44: 299 | AD44: 38 | AE44: 41 | AF44: 40 | AG44: 50 | AH44: 65 | AI44: 65
A45: 37 | B45: Vulpix (Alolan Form) | C45: 0037L0 | D45: 0.25 | E45: 0.75 | F45: Field | G45: Alola | H45: Ice | I45: - | J45: Basic | K45: 2 | L45: 0037A0 | M45: - | N45: Kid | O45: 1.25 | P45: - | AC45: 299 | AD45: 38 | AE45: 41 | AF45: 40 | AG45: 50 | AH45: 65 | AI45: 65
A46: 38 | B46: Ninetales | C46: 0038A0 | D46: 0.25 | E46: 0.75 | F46: Field | G46: Kanto | H46: Fire | I46: - | J46: Basic | K46: 2 | L46: 0037A0 | M46: 0037A0 | N46: Adult | O46: 1.25 | P46: Stone | AC46: 505 | AD46: 73 | AE46: 76 | AF46: 75 | AG46: 81 | AH46: 100 | AI46: 100
A47: 38 | B47: Ninetales (Alolan Form) | C47: 0038L0 | D47: 0.25 | E47: 0.75 | F47: Field | G47: Alola | H47: Ice | I47: Fairy | J47: Basic | K47: 2 | L47: 0037A0 | M47: 0037L0 | N47: Adult | O47: 1.25 | P47: Stone | AC47: 505 | AD47: 73 | AE47: 67 | AF47: 75 | AG47: 81 | AH47: 100 | AI47: 109
A48: 39 | B48: Jigglypuff | C48: 0039A0 | D48: 0.25 | E48: 0.75 | F48: Fairy | G48: Kanto | H48: Fairy | I48: Normal | J48: Basic | K48: 2 | L48: 0174A0 | M48: 0174A0 | N48: Kid | O48: 1.25 | P48: Experience | Q48: 1 | W48: felicidad | Y48: 70 | Z48: 6 | AC48: 270 | AD48: 115 | AE48: 45 | AF48: 20 | AG48: 45 | AH48: 25 | AI48: 20
A49: 40 | B49: Wigglytuff | C49: 0040A0 | D49: 0.25 | E49: 0.75 | F49: Fairy | G49: Kanto | H49: Fairy | I49: Normal | J49: Basic | K49: 2 | L49: 0174A0 | M49: 0039A0 | N49: Adult | O49: 1.25 | P49: Stone | Q49: 2 | V49: piedra_lunar | AC49: 435 | AD49: 140 | AE49: 70 | AF49: 45 | AG49: 85 | AH49: 50 | AI49: 45
A50: 41 | B50: Zubat | C50: 0041A0 | D50: 0.5 | E50: 0.5 | F50: Flying | G50: Kanto | H50: Poison | I50: Flying | J50: Basic | K50: 1 | L50: 0041A0 | M50: - | N50: Kid | O50: 1 | P50: - | AC50: 245 | AD50: 40 | AE50: 45 | AF50: 35 | AG50: 30 | AH50: 40 | AI50: 55
A51: 42 | B51: Golbat | C51: 0042A0 | D51: 0.5 | E51: 0.5 | F51: Flying | G51: Kanto | H51: Poison | I51: Flying | J51: Basic | K51: 1 | L51: 0041A0 | M51: 0041A0 | N51: Teen | O51: 1 | P51: Experience | AC51: 455 | AD51: 75 | AE51: 80 | AF51: 70 | AG51: 65 | AH51: 75 | AI51: 90
A52: 43 | B52: Oddish | C52: 0043A0 | D52: 0.5 | E52: 0.5 | F52: Grass | G52: Kanto | H52: Grass | I52: Poison | J52: Basic | K52: 1 | L52: 0043A0 | M52: - | N52: Kid | O52: 1 | P52: - | AC52: 320 | AD52: 45 | AE52: 50 | AF52: 55 | AG52: 75 | AH52: 65 | AI52: 30
A53: 44 | B53: Gloom | C53: 0044A0 | D53: 0.5 | E53: 0.5 | F53: Grass | G53: Kanto | H53: Grass | I53: Poison | J53: Basic | K53: 1 | L53: 0043A0 | M53: 0043A0 | N53: Teen | O53: 1 | P53: Experience | AC53: 395 | AD53: 60 | AE53: 65 | AF53: 70 | AG53: 85 | AH53: 75 | AI53: 40
...

Sheet Hoja3
A2: tiempo | B2: hambre
A3: stats | B3: felicidad
A4: objeto | B4: energía
A5: acción | B5: higiene
A6: caos
C8: edadMinima | D8: minHambre | E8: minFelicidad | F8: minEnergia | G8: minHigiene | H8: minStyle | I8: minIQ | J8: minKindness | K8: minStrength

Sheet LP Cost x Team
A1: LP Cost | B1: (Varios elementos)
A2: Stage | B2: (Varios elementos)
C4: Valores
A5: # | B5: Trainer | C5: Suma de LP Cost | D5: Suma de Overall
A6: 1 | B6: Red | C6: 26 | D6: 155
A7: 2 | B7: Blue | C7: 25 | D7: 158
A8: 3 | B8: Leaf | C8: 24 | D8: 153
A9: 4 | B9: Ethan | C9: 24 | D9: 147
A10: 5 | B10: Kris | C10: 23 | D10: 154
A11: 6 | B11: Lyra | C11: 23 | D11: 150
A12: 7 | B12: Silver | C12: 24 | D12: 151
A13: 8 | B13: Brendan | C13: 22 | D13: 141
A14: 9 | B14: May | C14: 22 | D14: 141
A15: 10 | B15: Wally | C15: 22 | D15: 145
A16: 11 | B16: Barry | C16: 24 | D16: 150
A17: 12 | B17: Lucas | C17: 23 | D17: 146
... A40: 100 | B40: Jomi | C40: 25 | D40: 157

Sheet Pokedex
B3: =VLOOKUP(C3,'Pokemon Db'!A:AP,2,0) -> Charizard | C3: 6 | E3: =CONCATENATE("#",C3," - ",B3) -> #6 - Charizard
E10: =VLOOKUP(C3,'Pokemon Db'!A:AP,19,0) -> 534
E11: =VLOOKUP(E10,Habs!B:D,3,0) -> #N/A
E13: =VLOOKUP(C3,'Pokemon Db'!A:AL,22,0) -> 78 | F13: =VLOOKUP(C3,'Pokemon Db'!A:AP,21,0) -> 84
E14: =VLOOKUP(F13,Movimientos!A:C,3,0) -> #N/A
E15: =VLOOKUP(C3,'Pokemon Db'!A:AL,24,0) -> 85 | F15: =VLOOKUP(C3,'Pokemon Db'!A:AP,23,0) -> 109
E16: =VLOOKUP(F15,Movimientos!A:C,3,0) -> #N/A
E18: W| | I18: |R

Sheet Evolution
A1: # | B1: Name | C1: Cod | D1: Family | E1: Preevolution | F1: Method | G1: Exp | H1: Evolves into | I1: Method | J1: Exp | K1: Friend | L1: Gender | M1: Move | N1: Weather | O1: Time | P1: Hability | Q1: PKMN in team | R1: Stat | S1: Name
A2: 1 | B2: Bulbasaur | C2: 001A | D2: 001A | E2: - | F2: - | G2: - | H2: Ivysaur | I2: Experience | J2: 3 | S2: Bulbasaur
A3: 2 | B3: Ivysaur | C3: 002A | D3: 001A | E3: 001A | F3: Experience | G3: 3 | H3: Venusaur | I3: Experience | J3: 4 | S3: Ivysaur
A4: 3 | B4: Venusaur | C4: 003A | D4: 001A | E4: 002A | F4: Experience | G4: 4 | H4: - | I4: - | J4: - | S4: Venusaur
A5: 4 | B5: Charmander | C5: 004A | D5: 004A | E5: - | F5: - | G5: - | H5: Charmeleon | I5: Experience | J5: 3 | S5: Charmander
A6: 5 | B6: Charmeleon | C6: 005A | D6: 004A | E6: 004A | F6: Experience | G6: 3 | H6: Charizard | I6: Experience | J6: 4 | S6: Charmeleon
A7: 6 | B7: Charizard | C7: 006A | D7: 004A | E7: 005A | F7: Experience | G7: 4 | H7: - | I7: - | J7: - | S7: Charizard
A8: 7 | B8: Squirtle | C8: 007A | D8: 007A | E8: - | F8: - | G8: - | H8: Wartortle | I8: Experience | J8: 3 | S8: Squirtle
A9: 8 | B9: Wartortle | C9: 008A | D9: 007A | E9: 007A | F9: Experience | G9: 3 | H9: Blastoise | I9: Experience | J9: 4 | S9: Wartortle
A10: 9 | B10: Blastoise | C10: 009A | D10: 007A | E10: 008A | F10: Experience | G10: 4 | H10: - | I10: - | J10: - | S10: Blastoise
A11: 10 | B11: Caterpie | C11: 010A | D11: 010A | E11: - | F11: - | G11: - | H11: Metapod | I11: Experience | J11: 2 | S11: Caterpie
A12: 11 | B12: Metapod | C12: 011A | D12: 010A | E12: 010A | F12: Experience | G12: 2 | H12: Butterfree | I12: Experience | J12: 2 | S12: Metapod
